Workbook

Sheet Вариант 1 (2)
A1: Номер счёта | B1: Дата | C1: Контрагент | D1: Сумма счёта | E1: Статус оплаты | F1: Наличие нарушений
A2: 1 | B2: 17.01.2024 | C2: ООО «Ромашка» | D2: 84900 | E2: Оплачен | F2: Нет | G2: дисп | H2: =_xlfn.VAR.P(D2:D501) -> 2.1736493e+09 | I2: =I7*I7 -> 62500 | J2: n= | K2: =(H2*4*500)/(H3^2*500+H2*4) -> 205.11353 | N2: сгенерировано | T2: подбор
A3: 2 | B3: 13.01.2024 | C3: АО «Вектор» | D3: 30700 | E3: Оплачен | F3: Нет | G3: дельта | H3: 5000 | I3: 5000 | J3: n по моей сигме | K3: =(I2*4*500)/(I3*500+I2*4) -> 45.454545 | M3: среднее | N3: сигма | O3: сигма2 | P3: v сигма | Q3: дельта | R3: n | S3: среднее | T3: сигма | U3: сигма2 | V3: v сигма | W3: дельта | X3: n
A4: 3 | B4: 14.08.2024 | C4: ИП Иванов И.И. | D4: 12200 | E4: Оплачен | F4: Нет | G4: макс | H4: =MAX(D2:D501) -> 263500 | L4: в1 | M4: =AVERAGE(D2:D501) -> 49621.399 | N4: =_xlfn.STDEV.P(D2:D501) -> 46622.412 | O4: =N4*N4 -> 2.1736493e+09 | P4: =N4/M4 -> 0.93956263 | Q4: 5000 | R4: =(O4*4*500)/(Q4^2*500+O4*4) -> 205.11353 | S4: 57520 | T4: =V4*S4 -> 14955.2 | U4: =T4*T4 -> 2.2365801e+08 | V4: 0.26 | W4: 1000 | X4: =(U4*4*500)/(W4^2*500+U4*4) -> 320.74125
A5: 4 | B5: 07.12.2024 | C5: ООО «Север» | D5: 110600 | E5: Оплачен | F5: Нет | G5: мин | H5: =MIN(D2:D501) -> 5000 | L5: в2 | M5: =AVERAGE('Вариант 2'!$D$2:$D$501) -> 50325.2 | N5: =_xlfn.STDEV.P('Вариант 2'!$D$2:$D$501) -> 53329.26 | O5: =N5*N5 -> 2.84401e+09 | P5: =N5/M5 -> 1.059693 | Q5: 5000 | R5: =(O5*4*500)/(Q5^2*500+O5*4) -> 238.2313 | S5: 50325.2 | T5: =V5*S5 -> 9058.536 | U5: =T5*T5 -> 82057074 | V5: 0.18 | W5: 5000 | X5: =(U5*4*500)/(W5^2*500+U5*4) -> 12.793205
A6: 5 | B6: 04.09.2024 | C6: ООО «Заря» | D6: 8200 | E6: Оплачен | F6: Нет | G6: срзнач | H6: =AVERAGE(D2:D501) -> 49621.399 | L6: в3 | M6: =AVERAGE('Вариант 3'!$D$2:$D$501) -> 55062.6 | N6: =_xlfn.STDEV.P('Вариант 3'!$D$2:$D$501) -> 71367.761 | O6: =N6*N6 -> 5.0933573e+09 | P6: =N6/M6 -> 1.2961204 | Q6: 5000 | R6: =(O6*4*500)/(Q6^2*500+O6*4) -> 309.87685 | S6: 55062.6 | T6: =V6*S6 -> 23126.292 | U6: =T6*T6 -> 5.3482538e+08 | V6: 0.42 | W6: 5000 | X6: =(U6*4*500)/(W6^2*500+U6*4) -> 73.067063
A7: 6 | B7: 10.09.2024 | C7: АО «Прогресс» | D7: 24600 | E7: Оплачен | F7: Да | G7: сигма | H7: =_xlfn.STDEV.P(D2:D501) -> 46622.412 | I7: 250 | L7: в4 | M7: =AVERAGE('Вариант 4'!$D$2:$D$501) -> 60321 | N7: =_xlfn.STDEV.P('Вариант 4'!$D$2:$D$501) -> 73393.448 | O7: =N7*N7 -> 5386598139 | P7: =N7/M7 -> 1.2167147 | Q7: 5000 | R7: =(O7*4*500)/(Q7^2*500+O7*4) -> 316.42695 | S7: 60321 | T7: =V7*S7 -> 17493.09 | U7: =T7*T7 -> 3.060082e+08 | V7: 0.29 | W7: 5000 | X7: =(U7*4*500)/(W7^2*500+U7*4) -> 44.594501
A8: 7 | B8: 07.02.2024 | C8: ООО «Кристалл» | D8: 37900 | E8: Частично | F8: Нет | L8: в5 | M8: =AVERAGE('Вариант 5'!$D$2:$D$501) -> 56871.8 | N8: =_xlfn.STDEV.P('Вариант 5'!$D$2:$D$501) -> 68864.36 | O8: =N8*N8 -> 4.7423001e+09 | P8: =N8/M8 -> 1.2108701 | Q8: 5000 | R8: =(O8*4*500)/(Q8^2*500+O8*4) -> 301.39311 | S8: 56871.8 | T8: =V8*S8 -> 11943.078 | U8: =T8*T8 -> 1.4263711e+08 | V8: 0.21 | W8: 5000 | X8: =(U8*4*500)/(W8^2*500+U8*4) -> 21.825727
A9: 8 | B9: 19.12.2024 | C9: ИП Петров П.П. | D9: 18300 | E9: Оплачен | F9: Нет | H9: 4500000000 | L9: в6 | M9: =AVERAGE('Вариант 6'!$D$2:$D$501) -> 81076.2 | N9: =_xlfn.STDEV.P('Вариант 6'!$D$2:$D$501) -> 89053.565 | O9: =N9*N9 -> 7.9305374e+09 | P9: =N9/M9 -> 1.0983934 | Q9: 5000 | R9: =(O9*4*500)/(Q9^2*500+O9*4) -> 358.66811 | S9: 81076.2 | T9: =V9*S9 -> 41348.862 | U9: =T9*T9 -> 1.7097284e+09 | V9: 0.51 | W9: 5000 | X9: =(U9*4*500)/(W9^2*500+U9*4) -> 176.81742
A10: 9 | B10: 11.12.2024 | C10: ООО «Альфа» | D10: 25900 | E10: Оплачен | F10: Нет | H10: =H2/H9 -> 0.48303319 | L10: в7 | M10: =AVERAGE('Вариант 7'!$D$2:$D$501) -> 34562.4 | N10: =_xlfn.STDEV.P('Вариант 7'!$D$2:$D$501) -> 51432.696 | O10: =N10*N10 -> 2.6453222e+09 | P10: =N10/M10 -> 1.4881112 | Q10: 5000 | R10: =(O10*4*500)/(Q10^2*500+O10*4) -> 229.21789 | S10: 34562.4 | T10: =V10*S10 -> 5875.608 | U10: =T10*T10 -> 34522769 | V10: 0.17 | W10: 5000 | X10: =(U10*4*500)/(W10^2*500+U10*4) -> 5.4632886
A11: 10 | B11: 05.03.2024 | C11: ООО «Бета» | D11: 65000 | E11: Оплачен | F11: Нет | L11: в8 | M11: =AVERAGE('Вариант 8'!$D$2:$D$501) -> 56566.2 | N11: =_xlfn.STDEV.P('Вариант 8'!$D$2:$D$501) -> 73265.768 | O11: =N11*N11 -> 5.3678727e+09 | P11: =N11/M11 -> 1.2952217 | Q11: 5000 | R11: =(O11*4*500)/(Q11^2*500+O11*4) -> 316.0222 | S11: 56566.2 | T11: =V11*S11 -> 14141.55 | U11: =T11*T11 -> 1.9998344e+08 | V11: 0.25 | W11: 5000 | X11: =(U11*4*500)/(W11^2*500+U11*4) -> 30.072847
A12: 11 | B12: 15.07.2024 | C12: АО «Гамма» | D12: 38400 | E12: Оплачен | F12: Нет | G12: V сигма | H12: =H7/H6*100 -> 93.956263 | L12: в9 | M12: =AVERAGE('Вариант 9'!$D$2:$D$501) -> 56878 | N12: =_xlfn.STDEV.P('Вариант 9'!$D$2:$D$501) -> 70966.299 | O12: =N12*N12 -> 5036215556 | P12: =N12/M12 -> 1.2476933 | Q12: 5000 | R12: =(O12*4*500)/(Q12^2*500+O12*4) -> 308.54568 | S12: 56878 | T12: =V12*S12 -> 15357.06 | U12: =T12*T12 -> 2.3583929e+08 | V12: 0.27 | W12: 5000 | X12: =(U12*4*500)/(W12^2*500+U12*4) -> 35.086369
A13: 12 | B13: 13.05.2024 | C13: ООО «Дельта» | D13: 263500 | E13: Оплачен | F13: Нет | L13: в10 | M13: =AVERAGE('Вариант 10'!$D$2:$D$501) -> 58319.8 | N13: =_xlfn.STDEV.P('Вариант 10'!$D$2:$D$501) -> 72627.337 | O13: =N13*N13 -> 5.2747301e+09 | P13: =N13/M13 -> 1.245329 | Q13: 5000 | R13: =(O13*4*500)/(Q13^2*500+O13*4) -> 313.98212 | S13: 58319.8 | T13: =V13*S13 -> 13413.554 | U13: =T13*T13 -> 1.7992343e+08 | V13: 0.23 | W13: 5000 | X13: =(U13*4*500)/(W13^2*500+U13*4) -> 27.220514
A14: 13 | B14: 08.12.2024 | C14: ООО «Ромашка» | D14: 29500 | E14: Оплачен | F14: Нет
A15: 14 | B15: 15.10.2024 | C15: АО «Вектор» | D15: 33200 | E15: Частично | F15: Нет | S15: 60432 | T15: =SQRT(U15) -> 42365.979 | U15: 1794876216 | V15: =T15/S15 -> 0.70105208 | W15: 5000 | X15: =(U15*4*500)/(W15^2*500+U15*4) -> 182.41071
A16: 15 | B16: 02.04.2024 | C16: ИП Иванов И.И. | D16: 107300 | E16: Оплачен | F16: Нет | H16: =H6+3*H7 -> 189488.64
A17: 16 | B17: 26.03.2024 | C17: ООО «Север» | D17: 93600 | E17: Не оплачен | F17: Нет | H17: =H6-3*H7 -> -90245.838
A18: 17 | B18: 09.01.2024 | C18: ООО «Заря» | D18: 127400 | E18: Оплачен | F18: Нет | K18: 1794876216
A19: 18 | B19: 11.07.2024 | C19: АО «Прогресс» | D19: 27100 | E19: Оплачен | F19: Да | G19: удаление нулевых и крупных выбросов в целом не решает проблему сильного разброса совокупности, V sigma остается порядка 93%
A20: 19 | B20: 26.03.2024 | C20: ООО «Кристалл» | D20: 65300 | E20: Не оплачен | F20: Нет | K20: 1794876216
A21: 20 | B21: 10.03.2024 | C21: ИП Петров П.П. | D21: 12800 | E21: Оплачен | F21: Нет | K21: 223000000
A22: 21 | B22: 17.03.2024 | C22: ООО «Альфа» | D22: 26300 | E22: Не оплачен | F22: Да | K22: 236160424
A23: 22 | B23: 15.04.2024 | C23: ООО «Бета» | D23: 19600 | E23: Оплачен | F23: Нет
A24: 23 | B24: 01.07.2024 | C24: АО «Гамма» | D24: 52400 | E24: Не оплачен | F24: Да
A25: 24 | B25: 08.04.2024 | C25: ООО «Дельта» | D25: 105900 | E25: Оплачен | F25: Нет
A26: 25 | B26: 31.07.2024 | C26: ООО «Ромашка» | D26: 29300 | E26: Оплачен | F26: Нет
A27: 26 | B27: 07.02.2024 | C27: АО «Вектор» | D27: 32600 | E27: Не оплачен | F27: Да
A28: 27 | B28: 11.03.2024 | C28: ИП Иванов И.И. | D28: 87700 | E28: Оплачен | F28: Нет
A29: 28 | B29: 03.01.2024 | C29: ООО «Север» | D29: 19300 | E29: Оплачен | F29: Нет
A30: 29 | B30: 27.02.2024 | C30: ООО «Заря» | D30: 121400 | E30: Оплачен | F30: Нет
A31: 30 | B31: 21.07.2024 | C31: АО «Прогресс» | D31: 6200 | E31: Частично | F31: Нет
A32: 31 | B32: 13.04.2024 | C32: ООО «Кристалл» | D32: 27600 | E32: Не оплачен | F32: Да
A33: 32 | B33: 20.11.2024 | C33: ИП Петров П.П. | D33: 36500 | E33: Оплачен | F33: Нет
A34: 33 | B34: 18.02.2024 | C34: ООО «Альфа» | D34: 29600 | E34: Частично | F34: Нет
... A50: 49 | B50: 11.03.2024 | C50: ООО «Ромашка» | D50: 92400 | E50: Оплачен | F50: Нет
A51: 50 | B51: 20.05.2024 | C51: АО «Вектор» | D51: 23900 | E51: Оплачен | F51: Нет | O51: =N51*N51 -> 0
A52: 51 | B52: 10.09.2024 | C52: ИП Иванов И.И. | D52: 158600 | E52: Оплачен | F52: Нет | O52: =N52*N52 -> 0
A53: 52 | B53: 11.02.2024 | C53: ООО «Север» | D53: 73400 | E53: Оплачен | F53: Нет | O53: =N53*N53 -> 0
A54: 53 | B54: 08.08.2024 | C54: ООО «Заря» | D54: 62300 | E54: Не оплачен | F54: Да | O54: =N54*N54 -> 0
A55: 54 | B55: 17.04.2024 | C55: АО «Прогресс» | D55: 16600 | E55: Оплачен | F55: Да | O55: =N55*N55 -> 0
...

Sheet Лист1
A3: Количество по полю Номер счета | B3: Названия столбцов
A4: Названия строк | B4: Да | C4: Нет | D4: Общий итог
A5: Не оплачен | B5: 55 | C5: 20 | D5: 75 | E5: Oij | I5: =GETPIVOTDATA("Контрагент",$A$3,"Статус оплаты","Не оплачен","Наличие нарушений","Да")^2/GETPIVOTDATA("Контрагент",$A$3,"Наличие нарушений","Да")/GETPIVOTDATA("Контрагент",$A$3,"Статус оплаты","Не оплачен") -> 0.40333333 | J5: =GETPIVOTDATA("Контрагент",$A$3,"Статус оплаты","Не оплачен","Наличие нарушений","Нет")^2/GETPIVOTDATA("Контрагент",$A$3,"Наличие нарушений","Нет")/GETPIVOTDATA("Контрагент",$A$3,"Статус оплаты","Не оплачен") -> 0.013333333
A6: Оплачен | B6: 35 | C6: 315 | D6: 350 | I6: =GETPIVOTDATA("Контрагент",$A$3,"Статус оплаты","Оплачен","Наличие нарушений","Да")^2/GETPIVOTDATA("Контрагент",$A$3,"Наличие нарушений","Да")/GETPIVOTDATA("Контрагент",$A$3,"Статус оплаты","Оплачен") -> 0.035 | J6: =GETPIVOTDATA("Контрагент",$A$3,"Статус оплаты","Оплачен","Наличие нарушений","Нет")^2/GETPIVOTDATA("Контрагент",$A$3,"Наличие нарушений","Нет")/GETPIVOTDATA("Контрагент",$A$3,"Статус оплаты","Оплачен") -> 0.70875
A7: Частично | B7: 10 | C7: 65 | D7: 75 | I7: =GETPIVOTDATA("Контрагент",$A$3,"Статус оплаты","Частично","Наличие нарушений","Да")^2/GETPIVOTDATA("Контрагент",$A$3,"Наличие нарушений","Да")/GETPIVOTDATA("Контрагент",$A$3,"Статус оплаты","Частично") -> 0.013333333 | J7: =GETPIVOTDATA("Контрагент",$A$3,"Статус оплаты","Частично","Наличие нарушений","Нет")^2/GETPIVOTDATA("Контрагент",$A$3,"Наличие нарушений","Нет")/GETPIVOTDATA("Контрагент",$A$3,"Статус оплаты","Частично") -> 0.14083333
A8: Общий итог | B8: 100 | C8: 400 | D8: 500 | I8: =SUM(I5:I7) -> 0.45166667 | J8: =SUM(J5:J7) -> 0.86291667 | K8: =I8+J8-1 -> 0.31458333
B10: =SUM(B5:C5)*SUM($B$5:$B$7)/GETPIVOTDATA("Контрагент",$A$3) -> 15 | C10: =SUM(B5:C5)*SUM($C$5:$C$7)/GETPIVOTDATA("Контрагент",$A$3) -> 60 | E10: Eij | J10: хи квадрат | K10: =K8*GETPIVOTDATA("Контрагент",$A$3) -> 157.29167
B11: =SUM(B6:C6)*SUM($B$5:$B$7)/GETPIVOTDATA("Контрагент",$A$3) -> 70 | C11: =SUM(B6:C6)*SUM($C$5:$C$7)/GETPIVOTDATA("Контрагент",$A$3) -> 280
B12: =SUM(B7:C7)*SUM($B$5:$B$7)/GETPIVOTDATA("Контрагент",$A$3) -> 15 | C12: =SUM(B7:C7)*SUM($C$5:$C$7)/GETPIVOTDATA("Контрагент",$A$3) -> 60
B14: =(GETPIVOTDATA("Контрагент",$A$3,"Статус оплаты","Не оплачен","Наличие нарушений","Да")-B10)^2/B10 -> 106.66667 | C14: =(GETPIVOTDATA("Контрагент",$A$3,"Статус оплаты","Не оплачен","Наличие нарушений","Нет")-C10)^2/C10 -> 26.666667 | E14: хи квадрат | I14: =(60-20)^2/60 -> 26.666667
B15: =(GETPIVOTDATA("Контрагент",$A$3,"Статус оплаты","Оплачен","Наличие нарушений","Да")-B11)^2/B11 -> 17.5 | C15: =(GETPIVOTDATA("Контрагент",$A$3,"Статус оплаты","Оплачен","Наличие нарушений","Нет")-C11)^2/C11 -> 4.375 | I15: =(55-15)^2/15 -> 106.66667
B16: =(GETPIVOTDATA("Контрагент",$A$3,"Статус оплаты","Частично","Наличие нарушений","Да")-B12)^2/B12 -> 1.6666667 | C16: =(GETPIVOTDATA("Контрагент",$A$3,"Статус оплаты","Частично","Наличие нарушений","Нет")-C12)^2/C12 -> 0.41666667
B17: =SUM(B14:B16) -> 125.83333 | C17: =SUM(C14:C16) -> 31.458333 | D17: =B17+C17 -> 157.29167
C18: чупров | D18: =SQRT(D17/(GETPIVOTDATA("Контрагент",$A$3)*SQRT(2*1))) -> 0.4716397
C19: пирсон | D19: =SQRT(D17/(500+D17)) -> 0.48918575
A22: Количество по полю Номер счета | B22: Названия столбцов
A23: Названия строк | B23: Да | C23: Нет | D23: Общий итог | I23: =39+295 -> 334
A24: Не оплачен | B24: =552 -> 552 | C24: 20 | D24: 75
A25: Оплачен | B25: 35 | C25: 315 | D25: 350 | I25: =91+334+75 -> 500
A26: Частично | B26: 10 | C26: 65 | D26: 75
A27: Общий итог | B27: 100 | C27: 400 | D27: 500 | I27: =51+39+10 -> 100
I29: =40+295+65 -> 400

Sheet Вариант 1
A1: Номер счёта | B1: Дата | C1: Контрагент | D1: Сумма счёта | E1: Статус оплаты | F1: Наличие нарушений
A2: 1 | B2: 17.01.2024 | C2: ООО «Ромашка» | D2: 84900 | E2: Оплачен | F2: Нет | G2: дисп | H2: =_xlfn.VAR.P(D2:D501) -> 5197103560 | I2: =I7*I7 -> 62500 | J2: n= | K2: =(H2*4*500)/(H3^2*500+H2*4) -> 312.24699 | N2: сгенерировано | T2: подбор
A3: 2 | B3: 13.01.2024 | C3: АО «Вектор» | D3: 30700 | E3: Оплачен | F3: Нет | G3: дельта | H3: 5000 | I3: 5000 | J3: n по моей сигме | K3: =(I2*4*500)/(I3*500+I2*4) -> 45.454545 | M3: среднее | N3: сигма | O3: сигма2 | P3: v сигма | Q3: дельта | R3: n | S3: среднее | T3: сигма | U3: сигма2 | V3: v сигма | W3: дельта | X3: n
A4: 3 | B4: 14.08.2024 | C4: ИП Иванов И.И. | D4: 12200 | E4: Оплачен | F4: Нет | G4: макс | H4: =MAX(D2:D501) -> 500000 | L4: в1 | M4: =AVERAGE(D2:D501) -> 57520 | N4: =_xlfn.STDEV.P(D2:D501) -> 72090.94 | O4: =N4*N4 -> 5197103560 | P4: =N4/M4 -> 1.2533195 | Q4: 5000 | R4: =(O4*4*500)/(Q4^2*500+O4*4) -> 312.24699 | S4: 57520 | T4: =V4*S4 -> 14955.2 | U4: =T4*T4 -> 2.2365801e+08 | V4: 0.26 | W4: 1000 | X4: =(U4*4*500)/(W4^2*500+U4*4) -> 320.74125
A5: 4 | B5: 07.12.2024 | C5: ООО «Север» | D5: 110600 | E5: Оплачен | F5: Нет | G5: мин | H5: =MIN(D2:D501) -> 0 | L5: в2 | M5: =AVERAGE('Вариант 2'!$D$2:$D$501) -> 50325.2 | N5: =_xlfn.STDEV.P('Вариант 2'!$D$2:$D$501) -> 53329.26 | O5: =N5*N5 -> 2.84401e+09 | P5: =N5/M5 -> 1.059693 | Q5: 5000 | R5: =(O5*4*500)/(Q5^2*500+O5*4) -> 238.2313 | S5: 50325.2 | T5: =V5*S5 -> 9058.536 | U5: =T5*T5 -> 82057074 | V5: 0.18 | W5: 5000 | X5: =(U5*4*500)/(W5^2*500+U5*4) -> 12.793205
A6: 5 | B6: 04.09.2024 | C6: ООО «Заря» | D6: 8200 | E6: Оплачен | F6: Нет | G6: срзнач | H6: =AVERAGE(D2:D501) -> 57520 | L6: в3 | M6: =AVERAGE('Вариант 3'!$D$2:$D$501) -> 55062.6 | N6: =_xlfn.STDEV.P('Вариант 3'!$D$2:$D$501) -> 71367.761 | O6: =N6*N6 -> 5.0933573e+09 | P6: =N6/M6 -> 1.2961204 | Q6: 5000 | R6: =(O6*4*500)/(Q6^2*500+O6*4) -> 309.87685 | S6: 55062.6 | T6: =V6*S6 -> 23126.292 | U6: =T6*T6 -> 5.3482538e+08 | V6: 0.42 | W6: 5000 | X6: =(U6*4*500)/(W6^2*500+U6*4) -> 73.067063
A7: 6 | B7: 10.09.2024 | C7: АО «Прогресс» | D7: 24600 | E7: Оплачен | F7: Да | G7: сигма | H7: =_xlfn.STDEV.P(D2:D501) -> 72090.94 | I7: 250 | L7: в4 | M7: =AVERAGE('Вариант 4'!$D$2:$D$501) -> 60321 | N7: =_xlfn.STDEV.P('Вариант 4'!$D$2:$D$501) -> 73393.448 | O7: =N7*N7 -> 5386598139 | P7: =N7/M7 -> 1.2167147 | Q7: 5000 | R7: =(O7*4*500)/(Q7^2*500+O7*4) -> 316.42695 | S7: 60321 | T7: =V7*S7 -> 17493.09 | U7: =T7*T7 -> 3.060082e+08 | V7: 0.29 | W7: 5000 | X7: =(U7*4*500)/(W7^2*500+U7*4) -> 44.594501
A8: 7 | B8: 07.02.2024 | C8: ООО «Кристалл» | D8: 37900 | E8: Частично | F8: Нет | L8: в5 | M8: =AVERAGE('Вариант 5'!$D$2:$D$501) -> 56871.8 | N8: =_xlfn.STDEV.P('Вариант 5'!$D$2:$D$501) -> 68864.36 | O8: =N8*N8 -> 4.7423001e+09 | P8: =N8/M8 -> 1.2108701 | Q8: 5000 | R8: =(O8*4*500)/(Q8^2*500+O8*4) -> 301.39311 | S8: 56871.8 | T8: =V8*S8 -> 11943.078 | U8: =T8*T8 -> 1.4263711e+08 | V8: 0.21 | W8: 5000 | X8: =(U8*4*500)/(W8^2*500+U8*4) -> 21.825727
A9: 8 | B9: 19.12.2024 | C9: ИП Петров П.П. | D9: 18300 | E9: Оплачен | F9: Нет | H9: 4500000000 | L9: в6 | M9: =AVERAGE('Вариант 6'!$D$2:$D$501) -> 81076.2 | N9: =_xlfn.STDEV.P('Вариант 6'!$D$2:$D$501) -> 89053.565 | O9: =N9*N9 -> 7.9305374e+09 | P9: =N9/M9 -> 1.0983934 | Q9: 5000 | R9: =(O9*4*500)/(Q9^2*500+O9*4) -> 358.66811 | S9: 81076.2 | T9: =V9*S9 -> 41348.862 | U9: =T9*T9 -> 1.7097284e+09 | V9: 0.51 | W9: 5000 | X9: =(U9*4*500)/(W9^2*500+U9*4) -> 176.81742
A10: 9 | B10: 11.12.2024 | C10: ООО «Альфа» | D10: 25900 | E10: Оплачен | F10: Нет | H10: =H2/H9 -> 1.1549119 | L10: в7 | M10: =AVERAGE('Вариант 7'!$D$2:$D$501) -> 34562.4 | N10: =_xlfn.STDEV.P('Вариант 7'!$D$2:$D$501) -> 51432.696 | O10: =N10*N10 -> 2.6453222e+09 | P10: =N10/M10 -> 1.4881112 | Q10: 5000 | R10: =(O10*4*500)/(Q10^2*500+O10*4) -> 229.21789 | S10: 34562.4 | T10: =V10*S10 -> 5875.608 | U10: =T10*T10 -> 34522769 | V10: 0.17 | W10: 5000 | X10: =(U10*4*500)/(W10^2*500+U10*4) -> 5.4632886
A11: 10 | B11: 05.03.2024 | C11: ООО «Бета» | D11: 65000 | E11: Оплачен | F11: Нет | L11: в8 | M11: =AVERAGE('Вариант 8'!$D$2:$D$501) -> 56566.2 | N11: =_xlfn.STDEV.P('Вариант 8'!$D$2:$D$501) -> 73265.768 | O11: =N11*N11 -> 5.3678727e+09 | P11: =N11/M11 -> 1.2952217 | Q11: 5000 | R11: =(O11*4*500)/(Q11^2*500+O11*4) -> 316.0222 | S11: 56566.2 | T11: =V11*S11 -> 14141.55 | U11: =T11*T11 -> 1.9998344e+08 | V11: 0.25 | W11: 5000 | X11: =(U11*4*500)/(W11^2*500+U11*4) -> 30.072847
A12: 11 | B12: 15.07.2024 | C12: АО «Гамма» | D12: 38400 | E12: Оплачен | F12: Нет | G12: V сигма | H12: =H7/H6*100 -> 125.33195 | L12: в9 | M12: =AVERAGE('Вариант 9'!$D$2:$D$501) -> 56878 | N12: =_xlfn.STDEV.P('Вариант 9'!$D$2:$D$501) -> 70966.299 | O12: =N12*N12 -> 5036215556 | P12: =N12/M12 -> 1.2476933 | Q12: 5000 | R12: =(O12*4*500)/(Q12^2*500+O12*4) -> 308.54568 | S12: 56878 | T12: =V12*S12 -> 15357.06 | U12: =T12*T12 -> 2.3583929e+08 | V12: 0.27 | W12: 5000 | X12: =(U12*4*500)/(W12^2*500+U12*4) -> 35.086369
A13: 12 | B13: 13.05.2024 | C13: ООО «Дельта» | D13: 263500 | E13: Оплачен | F13: Нет | L13: в10 | M13: =AVERAGE('Вариант 10'!$D$2:$D$501) -> 58319.8 | N13: =_xlfn.STDEV.P('Вариант 10'!$D$2:$D$501) -> 72627.337 | O13: =N13*N13 -> 5.2747301e+09 | P13: =N13/M13 -> 1.245329 | Q13: 5000 | R13: =(O13*4*500)/(Q13^2*500+O13*4) -> 313.98212 | S13: 58319.8 | T13: =V13*S13 -> 13413.554 | U13: =T13*T13 -> 1.7992343e+08 | V13: 0.23 | W13: 5000 | X13: =(U13*4*500)/(W13^2*500+U13*4) -> 27.220514
A14: 13 | B14: 08.12.2024 | C14: ООО «Ромашка» | D14: 29500 | E14: Оплачен | F14: Нет
A15: 14 | B15: 15.10.2024 | C15: АО «Вектор» | D15: 33200 | E15: Частично | F15: Нет | S15: 60432 | T15: =SQRT(U15) -> 42365.979 | U15: 1794876216 | V15: =T15/S15 -> 0.70105208 | W15: 5000 | X15: =(U15*4*500)/(W15^2*500+U15*4) -> 182.41071
A16: 15 | B16: 02.04.2024 | C16: ИП Иванов И.И. | D16: 107300 | E16: Оплачен | F16: Нет | H16: =H6+3*H7 -> 273792.82
A17: 16 | B17: 26.03.2024 | C17: ООО «Север» | D17: 93600 | E17: Не оплачен | F17: Нет | H17: =H6-3*H7 -> -158752.82
A18: 17 | B18: 09.01.2024 | C18: ООО «Заря» | D18: 127400 | E18: Оплачен | F18: Нет | K18: 1794876216
A19: 18 | B19: 11.07.2024 | C19: АО «Прогресс» | D19: 27100 | E19: Оплачен | F19: Да
A20: 19 | B20: 26.03.2024 | C20: ООО «Кристалл» | D20: 65300 | E20: Не оплачен | F20: Нет | K20: 1794876216
A21: 20 | B21: 10.03.2024 | C21: ИП Петров П.П. | D21: 12800 | E21: Оплачен | F21: Нет | K21: 223000000
A22: 21 | B22: 17.03.2024 | C22: ООО «Альфа» | D22: 26300 | E22: Не оплачен | F22: Да | K22: 236160424
A23: 22 | B23: 15.04.2024 | C23: ООО «Бета» | D23: 19600 | E23: Оплачен | F23: Нет
A24: 23 | B24: 01.07.2024 | C24: АО «Гамма» | D24: 52400 | E24: Не оплачен | F24: Да
A25: 24 | B25: 08.04.2024 | C25: ООО «Дельта» | D25: 105900 | E25: Оплачен | F25: Нет
A26: 25 | B26: 31.07.2024 | C26: ООО «Ромашка» | D26: 29300 | E26: Оплачен | F26: Нет
A27: 26 | B27: 07.02.2024 | C27: АО «Вектор» | D27: 32600 | E27: Не оплачен | F27: Да
A28: 27 | B28: 11.03.2024 | C28: ИП Иванов И.И. | D28: 87700 | E28: Оплачен | F28: Нет
A29: 28 | B29: 03.01.2024 | C29: ООО «Север» | D29: 19300 | E29: Оплачен | F29: Нет
A30: 29 | B30: 27.02.2024 | C30: ООО «Заря» | D30: 121400 | E30: Оплачен | F30: Нет
A31: 30 | B31: 21.07.2024 | C31: АО «Прогресс» | D31: 6200 | E31: Частично | F31: Нет
A32: 31 | B32: 13.04.2024 | C32: ООО «Кристалл» | D32: 27600 | E32: Не оплачен | F32: Да
A33: 32 | B33: 20.11.2024 | C33: ИП Петров П.П. | D33: 36500 | E33: Оплачен | F33: Нет
A34: 33 | B34: 18.02.2024 | C34: ООО «Альфа» | D34: 29600 | E34: Частично | F34: Нет
... A50: 49 | B50: 11.03.2024 | C50: ООО «Ромашка» | D50: 92400 | E50: Оплачен | F50: Нет
A51: 50 | B51: 20.05.2024 | C51: АО «Вектор» | D51: 23900 | E51: Оплачен | F51: Нет | O51: =N51*N51 -> 0
A52: 51 | B52: 10.09.2024 | C52: ИП Иванов И.И. | D52: 158600 | E52: Оплачен | F52: Нет | O52: =N52*N52 -> 0
A53: 52 | B53: 11.02.2024 | C53: ООО «Север» | D53: 73400 | E53: Оплачен | F53: Нет | O53: =N53*N53 -> 0
A54: 53 | B54: 08.08.2024 | C54: ООО «Заря» | D54: 62300 | E54: Не оплачен | F54: Да | O54: =N54*N54 -> 0
A55: 54 | B55: 17.04.2024 | C55: АО «Прогресс» | D55: 16600 | E55: Оплачен | F55: Да | O55: =N55*N55 -> 0
...

Sheet Вариант 2
A1: Номер счёта | B1: Дата | C1: Контрагент | D1: Сумма счёта | E1: Статус оплаты | F1: Наличие нарушений
A2: 1 | B2: 15.12.2024 | C2: ООО «СтройМонтаж» | D2: 42500 | E2: Оплачен | F2: Нет
A3: 2 | B3: 28.07.2024 | C3: АО «ГлавСтрой» | D3: 12900 | E3: Оплачен | F3: Нет
A4: 3 | B4: 15.10.2024 | C4: ООО «БетонСтрой» | D4: 97800 | E4: Оплачен | F4: Нет
A5: 4 | B5: 14.01.2024 | C5: ООО «Кирпич-Торг» | D5: 41800 | E5: Оплачен | F5: Нет
A6: 5 | B6: 23.08.2024 | C6: ИП Строев С.С. | D6: 17600 | E6: Оплачен | F6: Нет
A7: 6 | B7: 28.07.2024 | C7: ООО «Панель-Сервис» | D7: 87300 | E7: Оплачен | F7: Нет
A8: 7 | B8: 20.05.2024 | C8: ООО «Фундамент» | D8: 77500 | E8: Частично | F8: Нет
A9: 8 | B9: 19.10.2024 | C9: АО «Высота» | D9: 14600 | E9: Оплачен | F9: Нет
A10: 9 | B10: 22.10.2024 | C10: ООО «Кран-Сервис» | D10: 84600 | E10: Оплачен | F10: Нет
A11: 10 | B11: 20.08.2024 | C11: ООО «Леса-Торг» | D11: 26000 | E11: Оплачен | F11: Нет
A12: 11 | B12: 09.03.2024 | C12: ИП Плотников П.П. | D12: 20200 | E12: Оплачен | F12: Нет
A13: 12 | B13: 09.03.2024 | C13: ООО «СтройБаза» | D13: 65400 | E13: Оплачен | F13: Нет
... A501: 500 | B501: 19.10.2024 | C501: АО «Высота» | D501: 19000 | E501: Оплачен | F501: Нет

Sheet Вариант 3
A1: Номер счёта | B1: Дата | C1: Контрагент | D1: Сумма счёта | E1: Статус оплаты | F1: Наличие нарушений
A2: 1 | B2: 17.04.2024 | C2: ООО «ТоргСервис» | D2: 10200 | E2: Оплачен | F2: Да
A3: 2 | B3: 28.08.2024 | C3: АО «РитейлГрупп» | D3: 28000 | E3: Не оплачен | F3: Да
A4: 3 | B4: 09.09.2024 | C4: ООО «ОптТорг» | D4: 6500 | E4: Оплачен | F4: Нет
A5: 4 | B5: 13.10.2024 | C5: ООО «Розница-Плюс» | D5: 20600 | E5: Оплачен | F5: Нет
A6: 5 | B6: 23.07.2024 | C6: ИП Торговцев Т.Т. | D6: 30300 | E6: Оплачен | F6: Нет
A7: 6 | B7: 07.01.2024 | C7: ООО «ПродуктТорг» | D7: 169400 | E7: Частично | F7: Нет
A8: 7 | B8: 19.08.2024 | C8: ООО «МясоТорг» | D8: 169200 | E8: Не оплачен | F8: Да
A9: 8 | B9: 25.05.2024 | C9: АО «РыбТорг» | D9: 60400 | E9: Оплачен | F9: Нет
A10: 9 | B10: 22.07.2024 | C10: ООО «ОвощТорг» | D10: 59700 | E10: Не оплачен | F10: Нет
A11: 10 | B11: 04.12.2024 | C11: ООО «ФруктТорг» | D11: 45000 | E11: Частично | F11: Нет
A12: 11 | B12: 02.02.2024 | C12: ИП Ягодкин Я.Я. | D12: 51900 | E12: Оплачен | F12: Нет
A13: 12 | B13: 27.06.2024 | C13: ООО «МолокоТорг» | D13: 23400 | E13: Оплачен | F13: Нет
... A501: 500 | B501: 14.05.2024 | C501: АО «РыбТорг» | D501: 40600 | E501: Не оплачен | F501: Да

Sheet Вариант 4
A1: Номер счёта | B1: Дата | C1: Контрагент | D1: Сумма счёта | E1: Статус оплаты | F1: Наличие нарушений
A2: 1 | B2: 09.02.2024 | C2: ООО «Логистик-1» | D2: 35300 | E2: Оплачен | F2: Да
A3: 2 | B3: 17.11.2024 | C3: АО «ТрансЛогистик» | D3: 32800 | E3: Не оплачен | F3: Да
A4: 3 | B4: 12.07.2024 | C4: ООО «СкладСервис» | D4: 44200 | E4: Оплачен | F4: Нет
A5: 4 | B5: 30.11.2024 | C5: ООО «Грузоперевозки» | D5: 36600 | E5: Частично | F5: Нет
A6: 5 | B6: 19.01.2024 | C6: ИП Перевозчиков П.П. | D6: 107800 | E6: Не оплачен | F6: Да
A7: 6 | B7: 19.08.2024 | C7: ООО «Экспресс-Доставка» | D7: 133300 | E7: Частично | F7: Да
A8: 7 | B8: 24.01.2024 | C8: ООО «Курьер-Сервис» | D8: 35000 | E8: Не оплачен | F8: Да
A9: 8 | B9: 25.01.2024 | C9: АО «Почта-Логистик» | D9: 26800 | E9: Не оплачен | F9: Да
A10: 9 | B10: 04.11.2024 | C10: ООО «Склад-Торг» | D10: 53600 | E10: Оплачен | F10: Да
A11: 10 | B11: 04.09.2024 | C11: ООО «Терминал-Плюс» | D11: 12700 | E11: Не оплачен | F11: Да
A12: 11 | B12: 19.06.2024 | C12: ИП Логистов Л.Л. | D12: 45100 | E12: Оплачен | F12: Нет
A13: 12 | B13: 29.03.2024 | C13: ООО «Карго-Сервис» | D13: 13400 | E13: Оплачен | F13: Нет
... A501: 500 | B501: 17.03.2024 | C501: АО «Почта-Логистик» | D501: 30200 | E501: Оплачен | F501: Нет

Sheet Вариант 5
A1: Номер счёта | B1: Дата | C1: Контрагент | D1: Сумма счёта | E1: Статус оплаты | F1: Наличие нарушений
A2: 1 | B2: 09.09.2024 | C2: ООО «АйТи-Сервис» | D2: 17700 | E2: Оплачен | F2: Нет
A3: 2 | B3: 28.05.2024 | C3: АО «Софт-Групп» | D3: 29300 | E3: Оплачен | F3: Нет
A4: 3 | B4: 04.01.2024 | C4: ООО «Хард-Сервис» | D4: 20100 | E4: Частично | F4: Нет
A5: 4 | B5: 22.01.2024 | C5: ООО «Веб-Студия» | D5: 30000 | E5: Не оплачен | F5: Нет
A6: 5 | B6: 24.07.2024 | C6: ИП Программистов П.П. | D6: 92600 | E6: Оплачен | F6: Нет
A7: 6 | B7: 18.10.2024 | C7: ООО «Девелопер-Сервис» | D7: 19100 | E7: Оплачен | F7: Нет
A8: 7 | B8: 06.11.2024 | C8: ООО «Аналитик-Софт» | D8: 21200 | E8: Оплачен | F8: Нет
A9: 8 | B9: 19.10.2024 | C9: АО «Дата-Центр» | D9: 227600 | E9: Оплачен | F9: Нет
A10: 9 | B10: 07.03.2024 | C10: ООО «Клауд-Сервис» | D10: 5100 | E10: Оплачен | F10: Нет
A11: 10 | B11: 05.01.2024 | C11: ООО «Секьюрити-Софт» | D11: 19000 | E11: Оплачен | F11: Нет
A12: 11 | B12: 06.01.2024 | C12: ИП Разработчиков Р.Р. | D12: 76900 | E12: Оплачен | F12: Нет
A13: 12 | B13: 17.04.2024 | C13: ООО «Тест-Софт» | D13: 21300 | E13: Оплачен | F13: Нет
... A501: 500 | B501: 21.07.2024 | C501: АО «Дата-Центр» | D501: 65000 | E501: Оплачен | F501: Нет

Sheet Вариант 6
A1: Номер счёта | B1: Дата | C1: Контрагент | D1: Сумма счёта | E1: Статус оплаты | F1: Наличие нарушений
A2: 1 | B2: 04.03.2024 | C2: ООО «МедСервис» | D2: 152800 | E2: Оплачен | F2: Нет
A3: 2 | B3: 19.12.2024 | C3: АО «ФармГрупп» | D3: 8800 | E3: Оплачен | F3: Нет
A4: 3 | B4: 19.08.2024 | C4: ООО «Аптека-Сервис» | D4: 117200 | E4: Оплачен | F4: Нет
A5: 4 | B5: 21.07.2024 | C5: ООО «МедТех-Торг» | D5: 269600 | E5: Оплачен | F5: Нет
A6: 5 | B6: 23.12.2024 | C6: ИП Врачов В.В. | D6: 95300 | E6: Оплачен | F6: Нет
A7: 6 | B7: 17.04.2024 | C7: ООО «Клиника-Плюс» | D7: 198500 | E7: Не оплачен | F7: Да
A8: 7 | B8: 11.04.2024 | C8: ООО «Диагностика-Сервис» | D8: 35800 | E8: Оплачен | F8: Нет
A9: 8 | B9: 14.01.2024 | C9: АО «Лаборатория-Групп» | D9: 10500 | E9: Оплачен | F9: Нет
A10: 9 | B10: 24.09.2024 | C10: ООО «Анализ-Сервис» | D10: 38100 | E10: Оплачен | F10: Нет
A11: 10 | B11: 18.06.2024 | C11: ООО «МедОборудование» | D11: 192300 | E11: Не оплачен | F11: Нет
A12: 11 | B12: 10.03.2024 | C12: ИП Медсестров М.М. | D12: 187000 | E12: Оплачен | F12: Нет
A13: 12 | B13: 24.03.2024 | C13: ООО «Стоматология-Сервис» | D13: 39600 | E13: Оплачен | F13: Нет
... A501: 500 | B501: 23.11.2024 | C501: АО «Лаборатория-Групп» | D501: 103000 | E501: Оплачен | F501: Нет

Sheet Вариант 7
A1: Номер счёта | B1: Дата | C1: Контрагент | D1: Сумма счёта | E1: Статус оплаты | F1: Наличие нарушений
A2: 1 | B2: 03.01.2024 | C2: ООО «Завод-1» | D2: 8200 | E2: Оплачен | F2: Нет
A3: 2 | B3: 24.07.2024 | C3: АО «Металлург» | D3: 6900 | E3: Оплачен | F3: Нет
A4: 3 | B4: 30.10.2024 | C4: ООО «Прокат-Сервис» | D4: 23100 | E4: Оплачен | F4: Нет
A5: 4 | B5: 28.11.2024 | C5: ООО «Литьё-Сервис» | D5: 41600 | E5: Оплачен | F5: Да
A6: 5 | B6: 29.06.2024 | C6: ИП Металлистов М.М. | D6: 32700 | E6: Оплачен | F6: Да
A7: 6 | B7: 28.11.2024 | C7: ООО «Прокат-Плюс» | D7: 25700 | E7: Оплачен | F7: Нет
A8: 7 | B8: 11.06.2024 | C8: ООО «Литьё-Плюс» | D8: 6700 | E8: Оплачен | F8: Нет
A9: 8 | B9: 18.06.2024 | C9: АО «Сталь-Групп» | D9: 67800 | E9: Не оплачен | F9: Нет
A10: 9 | B10: 03.05.2024 | C10: ООО «Чугун-Сервис» | D10: 5000 | E10: Оплачен | F10: Нет
A11: 10 | B11: 22.03.2024 | C11: ООО «Алюминий-Сервис» | D11: 11300 | E11: Оплачен | F11: Нет
A12: 11 | B12: 04.10.2024 | C12: ИП Алюминиев А.А. | D12: 12400 | E12: Оплачен | F12: Нет
A13: 12 | B13: 09.11.2024 | C13: ООО «Медь-Сервис» | D13: 113900 | E13: Частично | F13: Нет
... A501: 500 | B501: 14.09.2024 | C501: АО «Сталь-Групп» | D501: 46300 | E501: Оплачен | F501: Нет

Sheet Вариант 8
A1: Номер счёта | B1: Дата | C1: Контрагент | D1: Сумма счёта | E1: Статус оплаты | F1: Наличие нарушений
A2: 1 | B2: 29.04.2024 | C2: ООО «ФинСервис» | D2: 23400 | E2: Не оплачен | F2: Да
A3: 2 | B3: 25.04.2024 | C3: АО «Банк-Групп» | D3: 13700 | E3: Частично | F3: Нет
A4: 3 | B4: 24.12.2024 | C4: ООО «Кредит-Сервис» | D4: 307500 | E4: Оплачен | F4: Да
A5: 4 | B5: 20.08.2024 | C5: ООО «Депозит-Сервис» | D5: 167100 | E5: Не оплачен | F5: Да
A6: 5 | B6: 26.07.2024 | C6: ИП Банкиров Б.Б. | D6: 5000 | E6: Оплачен | F6: Нет
A7: 6 | B7: 23.08.2024 | C7: ООО «Инвест-Плюс» | D7: 87600 | E7: Не оплачен | F7: Да
A8: 7 | B8: 05.04.2024 | C8: ООО «Фонд-Сервис» | D8: 23000 | E8: Оплачен | F8: Да
A9: 8 | B9: 09.08.2024 | C9: АО «Страх-Групп» | D9: 26200 | E9: Не оплачен | F9: Да
A10: 9 | B10: 27.09.2024 | C10: ООО «Лизинг-Сервис» | D10: 45100 | E10: Оплачен | F10: Нет
A11: 10 | B11: 08.02.2024 | C11: ООО «Факторинг-Сервис» | D11: 8100 | E11: Оплачен | F11: Нет
A12: 11 | B12: 05.01.2024 | C12: ИП Факторингов Ф.Ф. | D12: 9100 | E12: Частично | F12: Нет
A13: 12 | B13: 03.07.2024 | C13: ООО «Брокер-Сервис» | D13: 16400 | E13: Не оплачен | F13: Да
... A501: 500 | B501: 03.02.2024 | C501: АО «Страх-Групп» | D501: 15400 | E501: Оплачен | F501: Нет

Sheet Вариант 9
A1: Номер счёта | B1: Дата | C1: Контрагент | D1: Сумма счёта | E1: Статус оплаты | F1: Наличие нарушений
A2: 1 | B2: 27.03.2024 | C2: ООО «Транс-1» | D2: 69900 | E2: Оплачен | F2: Нет
A3: 2 | B3: 15.01.2024 | C3: АО «АвтоТранс» | D3: 109300 | E3: Оплачен | F3: Нет
A4: 3 | B4: 04.09.2024 | C4: ООО «ЖД-Сервис» | D4: 69000 | E4: Оплачен | F4: Да
A5: 4 | B5: 25.12.2024 | C5: ООО «Авиа-Сервис» | D5: 32600 | E5: Оплачен | F5: Нет
A6: 5 | B6: 19.05.2024 | C6: ИП Перевозчиков П.П. | D6: 66900 | E6: Оплачен | F6: Нет
A7: 6 | B7: 01.11.2024 | C7: ООО «Мор-Сервис» | D7: 105300 | E7: Оплачен | F7: Да
A8: 7 | B8: 04.05.2024 | C8: ООО «Реч-Сервис» | D8: 73400 | E8: Не оплачен | F8: Нет
A9: 8 | B9: 08.05.2024 | C9: АО «Труб-Групп» | D9: 335600 | E9: Оплачен | F9: Нет
A10: 9 | B10: 10.02.2024 | C10: ООО «Газ-Сервис» | D10: 24100 | E10: Не оплачен | F10: Нет
A11: 10 | B11: 26.12.2024 | C11: ООО «Нефть-Сервис» | D11: 30500 | E11: Оплачен | F11: Нет
A12: 11 | B12: 23.09.2024 | C12: ИП Нефтяников Н.Н. | D12: 85900 | E12: Оплачен | F12: Да
A13: 12 | B13: 24.09.2024 | C13: ООО «Хим-Сервис» | D13: 66100 | E13: Не оплачен | F13: Да
... A501: 500 | B501: 04.12.2024 | C501: АО «Труб-Групп» | D501: 22400 | E501: Оплачен | F501: Нет

Sheet Вариант 10
A1: Номер счёта | B1: Дата | C1: Контрагент | D1: Сумма счёта | E1: Статус оплаты | F1: Наличие нарушений
A2: 1 | B2: 12.03.2024 | C2: ООО «Птица-Сервис» | D2: 0 | E2: Не оплачен | F2: Нет
A3: 2 | B3: 06.08.2024 | C3: ООО «Молоко-Сервис» | D3: 0 | E3: Частично | F3: Нет
A4: 3 | B4: 12.01.2024 | C4: АО «Свиновод-Групп» | D4: 0 | E4: Оплачен | F4: Нет
A5: 4 | B5: 23.03.2024 | C5: ИП Овцеводов О.О. | D5: 5000 | E5: Оплачен | F5: Нет
A6: 5 | B6: 03.03.2024 | C6: ООО «Мясо-Сервис» | D6: 5000 | E6: Оплачен | F6: Нет
A7: 6 | B7: 15.07.2024 | C7: АО «Свиновод-Групп» | D7: 5000 | E7: Частично | F7: Нет
A8: 7 | B8: 18.12.2024 | C8: АО «АгроХолдинг» | D8: 5000 | E8: Оплачен | F8: Нет
A9: 8 | B9: 04.10.2024 | C9: АО «Свиновод-Групп» | D9: 5000 | E9: Не оплачен | F9: Да
A10: 9 | B10: 04.07.2024 | C10: ООО «Овца-Сервис» | D10: 5000 | E10: Оплачен | F10: Нет
A11: 10 | B11: 27.10.2024 | C11: АО «АгроХолдинг» | D11: 5000 | E11: Оплачен | F11: Да
A12: 11 | B12: 25.12.2024 | C12: ИП Фермеров Ф.Ф. | D12: 5000 | E12: Оплачен | F12: Да
A13: 12 | B13: 08.01.2024 | C13: АО «АгроХолдинг» | D13: 5000 | E13: Оплачен | F13: Нет
... A501: 500 | B501: 26.11.2024 | C501: АО «АгроХолдинг» | D501: 500000 | E501: Не оплачен | F501: Да
